<?xml version="1.0"?>
<robot name="model" xmlns:xacro="http://www.ros.org/wiki/xacro">
  
  <!--differential drive system-->
  <gazebo>
    <plugin filename="libgazebo_ros_diff_drive.so" name="differential_drive_controller">
      <alwaysOn>true</alwaysOn>
      <updateRate>20</updateRate>
      <leftJoint>joint_left_wheel</leftJoint>
      <rightJoint>joint_right_wheel</rightJoint>
      <wheelSeparation>0.7</wheelSeparation>
      <wheelDiameter>0.2</wheelDiameter>
      <torque>1</torque>
      <commandTopic>cmd_vel</commandTopic>
      <odometryTopic>odom</odometryTopic>
      <odometryFrame>odom</odometryFrame>
      <robotBaseFrame>link_chassis</robotBaseFrame>
    </plugin>
  </gazebo>
  
  
   <link name="link_chassis">
    <!--pose and inertial-->
    <pose>0 0 0.1 0 0 0</pose>
    <inertial>
      <mass value="15"/>
      <origin rpy="0 0 0" xyz="0 0 0.1"/>
      <inertia ixx="0.165" ixy="0" ixz="0" iyy="0.2115" iyz="0" izz="0.099"/>
    </inertial>
    <!--body -->
    <collision name="chassis_collision">
      <geometry>
        <box size="0.65 0.6 0.07"/>
      </geometry>
    </collision>
    <visual>
      <origin rpy="0 0 0" xyz="0 0 0"/>
      <geometry>
        <box size="0.65 0.6 0.07"/>
      </geometry>
    </visual>
    <!--caster sphere-->
    <collision name="caster_collision">
      <origin rpy=" 0 0 0" xyz="-0.25 0 -0.03"/>
      <geometry>
        <sphere radius="0.07"/>
      </geometry>
      <surface>
        <friction>
          <ode>
            <mu></mu>
            <mu2></mu2>
            <slip1>1.0</slip1>
            <slip2>1.0</slip2>
          </ode>
        </friction>
      </surface>
    </collision>
    <visual name="caster_visual">
      <origin rpy=" 0 0 0" xyz="-0.15 0 -0.03"/>
      <geometry>
        <sphere radius="0.07"/>
      </geometry>
    </visual>
  </link>
  
  <!--wheels and joints-->
  <link name="link_right_wheel">
    <inertial>
      <mass value="2"/>
      <origin rpy="0 1.5707 1.5707" xyz="0 0 0"/>
      <inertia ixx="0.005" ixy="0" ixz="0" iyy="0.005" iyz="0" izz="0.01"/>
    </inertial>
    <collision name="link_right_wheel_collision">
      <origin rpy="0 1.5707 1.5707" xyz="0 0 0"/>
      <geometry>
        <cylinder length="0.05" radius="0.1"/>
      </geometry>
    </collision>
    <visual name="link_right_wheel_visual">
      <origin rpy="0 1.5707 1.5707" xyz="0 0 0"/>
      <geometry>
        <cylinder length="0.05" radius="0.1"/>
      </geometry>
    </visual>
  </link>
  
  <joint name="joint_right_wheel" type="continuous">
    <origin rpy="0 0 0" xyz="0.1 0.3 0"/>
    <child link="link_right_wheel"/>
    <parent link="link_chassis"/>
    <axis rpy="0 0 0" xyz="0 1 0"/>
  </joint>
  
  <link name="link_left_wheel">
    <inertial>
      <mass value="2"/>
      <origin rpy="0 1.5707 1.5707" xyz="0 0 0"/>
      <inertia ixx="0.005" ixy="0" ixz="0" iyy="0.005" iyz="0" izz="0.01"/>
    </inertial>
    <collision name="link_left_wheel_collision">
      <origin rpy="0 1.5707 1.5707" xyz="0 0 0"/>
      <geometry>
        <cylinder length="0.05" radius="0.1"/>
      </geometry>
    </collision>
    <visual name="link_left_wheel_visual">
      <origin rpy="0 1.5707 1.5707" xyz="0 0 0"/>
      <geometry>
        <cylinder length="0.05" radius="0.1"/>
      </geometry>
    </visual>
  </link>
  
  <joint name="joint_left_wheel" type="continuous">
    <origin rpy="0 0 0" xyz="0.1 -0.3 0"/>
    <child link="link_left_wheel"/>
    <parent link="link_chassis"/>
    <axis rpy="0 0 0" xyz="0 1 0"/>
  </joint>


  <!--ultrasonic boxes and joints-->
  <link name="ultrasonic_linkL">
    <inertial>
      <mass value="0.5"/>
      <origin rpy="0 0 0" xyz="0 0 0.1"/>
      <inertia ixx="0.00001" ixy="0" ixz="0" iyy="0.00001" iyz="0" izz="0.00001"/>
    </inertial>
    <collision name="ultrasonicL_collision">
      <origin rpy="0 0 0" xyz="0 0 0"/>
      <geometry>
        <box size="0.01 0.01 0.01"/>
      </geometry>
    </collision>
    <visual>
      <origin rpy="0 0 0" xyz="0 0 0"/>
      <geometry>
        <box size="0.01 0.01 0.01"/>
      </geometry>
    </visual>
  </link>

  <link name="ultrasonic_linkR">
    <inertial>
      <mass value="0.5"/>
      <origin rpy="0 0 0" xyz="0 0 0.1"/>
      <inertia ixx="0.00001" ixy="0" ixz="0" iyy="0.00001" iyz="0" izz="0.00001"/>
    </inertial>
    <collision name="ultrasonicR_collision">
      <origin rpy="0 0 0" xyz="0 0 0"/>
      <geometry>
        <box size="0.01 0.01 0.01"/>
      </geometry>
    </collision>
    <visual>
      <origin rpy="0 0 0" xyz="0 0 0"/>
      <geometry>
        <box size="0.01 0.01 0.01"/>
      </geometry>
    </visual>
  </link>

  <joint name="joint_ultrasonicL" type="fixed">
    <origin rpy="0 0 0.45" xyz="0.325 0.2 0.03"/>
    <child link="ultrasonic_linkL"/>
    <parent link="link_chassis"/>
  </joint>

  <joint name="joint_ultrasonicR" type="fixed">
    <origin rpy="0 0 -0.45" xyz="0.325 -0.2 0.03"/>
    <child link="ultrasonic_linkR"/>
    <parent link="link_chassis"/>
  </joint>



  <!--camera box and joint-->
  <link name="link_camera">
    <inertial>
      <mass value="1"/>
      <origin rpy="0 0 0" xyz="0 0 0.1"/>
      <inertia ixx="0.000017" ixy="0" ixz="0" iyy="0.000017" iyz="0" izz="0.000017"/>
    </inertial>
    <collision name="collision_camera">
      <origin rpy="0 0 0" xyz="0 0 0"/>
      <geometry>
        <box size="0.07 0.07 0.07"/>
      </geometry>
    </collision>
    <visual>
      <origin rpy="0 0 0" xyz="0 0 0"/>
      <geometry>
        <box size="0.07 0.07 0.07"/>
      </geometry>
    </visual>
  </link>

  <joint name="joint_camera" type="fixed">
    <origin rpy="0 0 0" xyz="0.2 0 0.05"/>
    <child link="link_camera"/>
    <parent link="link_chassis"/>
  </joint>


  <!--camera plugin-->
  <gazebo reference="link_camera">
    <sensor type="depth" name="camera">       
      <always_on>true</always_on>
      <visualize>true</visualize>             
      <camera>
          <horizontal_fov>1.047</horizontal_fov>
          <image>
              <width>752</width>
              <height>480</height>
              <format>R8G8B8</format>
          </image>
          <clip>
              <near>0.02</near>
              <far>300</far>
          </clip>
          <noise>
            <type>gaussian</type>
            <mean>0.0</mean>
            <stddev>0.007</stddev>
          </noise>
      </camera>
      <plugin name="camera_controller" filename="libgazebo_ros_openni_kinect.so">
          <baseline>0.2</baseline>
          <alwaysOn>true</alwaysOn>
          <updateRate>10.0</updateRate>
          <cameraName>mynteye</cameraName>
          <frameName>link_camera</frameName>                   
          <imageTopicName>rgb/image_raw</imageTopicName>
          <depthImageTopicName>depth/image_raw</depthImageTopicName>
          <pointCloudTopicName>depth/points</pointCloudTopicName>
          <cameraInfoTopicName>rgb/camera_info</cameraInfoTopicName>              
          <depthImageCameraInfoTopicName>depth/camera_info</depthImageCameraInfoTopicName>            
          <pointCloudCutoff>0.4</pointCloudCutoff>                
          <hackBaseline>0.07</hackBaseline>
          <distortionK1>0.0</distortionK1>
          <distortionK2>0.0</distortionK2>
          <distortionK3>0.0</distortionK3>
          <distortionT1>0.0</distortionT1>
          <distortionT2>0.0</distortionT2>
          <CxPrime>0.0</CxPrime>
          <Cx>0.0</Cx>
          <Cy>0.0</Cy>
          <focalLength>0.0</focalLength>
       </plugin>
    </sensor>
  </gazebo>

  <!--ultrasonic plugins-->
  <gazebo reference="ultrasonic_linkL">
    <sensor type="ray" name="sonar">
        <update_rate>5</update_rate>
        <ray>
          <scan>
            <horizontal>
              <samples>5</samples>
              <resolution>1.0</resolution>
              <min_angle>-0.25</min_angle>
              <max_angle>0.25</max_angle>
            </horizontal>
            <vertical>
              <samples>5</samples>
              <resolution>1</resolution>
	      <!--min vertical angles smaller to keep from sensing the ground-->
              <min_angle>-0.1</min_angle>
              <max_angle>0.1</max_angle>
            </vertical>
          </scan>
          <range>
            <min>0.01</min>
            <max>1</max>
            <resolution>0.01</resolution>
          </range>
        </ray>
        <plugin filename="libgazebo_ros_range.so" name="gazebo_ros_range">
          <gaussianNoise>0.005</gaussianNoise>
          <alwaysOn>true</alwaysOn>
          <updateRate>5</updateRate>
          <topicName>sonarL</topicName>
          <frameName>sonar_linkL</frameName>
          <fov>0.5</fov>
          <radiation>ultrasound</radiation>
        </plugin>
      </sensor>
  </gazebo>

  <gazebo reference="ultrasonic_linkR">
    <sensor type="ray" name="sonar">
        <update_rate>5</update_rate>
        <ray>
          <scan>
            <horizontal>
              <samples>5</samples>
              <resolution>1.0</resolution>
              <min_angle>-0.25</min_angle>
              <max_angle>0.25</max_angle>
            </horizontal>
            <vertical>
              <samples>5</samples>
              <resolution>1</resolution>
	      <!--min vertical angles smaller to keep from sensing the ground-->
              <min_angle>-0.1</min_angle>
              <max_angle>0.1</max_angle>
            </vertical>
          </scan>
          <range>
            <min>0.01</min>
            <max>1</max>
            <resolution>0.01</resolution>
          </range>
        </ray>
        <plugin filename="libgazebo_ros_range.so" name="gazebo_ros_range">
          <gaussianNoise>0.005</gaussianNoise>
          <alwaysOn>true</alwaysOn>
          <updateRate>5</updateRate>
          <topicName>sonarR</topicName>
          <frameName>sonar_linkR</frameName>
          <fov>0.5</fov>
          <radiation>ultrasound</radiation>
        </plugin>
      </sensor>
  </gazebo>

</robot>
